INFO - Bubble Sort - Running command 'bubbleSort'
WARNING - telegram.vendor.ptb_urllib3.urllib3.connectionpool - Retrying (Retry(total=2, connect=None, read=None, redirect=None)) after connection broken by 'NewConnectionError('<telegram.vendor.ptb_urllib3.urllib3.connection.VerifiedHTTPSConnection object at 0x7f92d8080cf8>: Failed to establish a new connection: [Errno -3] Temporary failure in name resolution',)': /bot350553078:AAEu70JDqMFcG_x5eBD3nqccTvc4aFNMKkg/sendMessage
WARNING - telegram.vendor.ptb_urllib3.urllib3.connectionpool - Retrying (Retry(total=1, connect=None, read=None, redirect=None)) after connection broken by 'NewConnectionError('<telegram.vendor.ptb_urllib3.urllib3.connection.VerifiedHTTPSConnection object at 0x7f92d8080550>: Failed to establish a new connection: [Errno -3] Temporary failure in name resolution',)': /bot350553078:AAEu70JDqMFcG_x5eBD3nqccTvc4aFNMKkg/sendMessage
WARNING - telegram.vendor.ptb_urllib3.urllib3.connectionpool - Retrying (Retry(total=0, connect=None, read=None, redirect=None)) after connection broken by 'NewConnectionError('<telegram.vendor.ptb_urllib3.urllib3.connection.VerifiedHTTPSConnection object at 0x7f92d8080080>: Failed to establish a new connection: [Errno -3] Temporary failure in name resolution',)': /bot350553078:AAEu70JDqMFcG_x5eBD3nqccTvc4aFNMKkg/sendMessage
WARNING - telegram-observer - failed to send start_event message via telegram.
Traceback (most recent call last):
  File "/home/julius/anaconda3/lib/python3.5/site-packages/telegram/vendor/ptb_urllib3/urllib3/connection.py", line 141, in _new_conn
    (self.host, self.port), self.timeout, **extra_kw)
  File "/home/julius/anaconda3/lib/python3.5/site-packages/telegram/vendor/ptb_urllib3/urllib3/util/connection.py", line 60, in create_connection
    for res in socket.getaddrinfo(host, port, family, socket.SOCK_STREAM):
  File "/home/julius/anaconda3/lib/python3.5/socket.py", line 732, in getaddrinfo
    for res in _socket.getaddrinfo(host, port, family, type, proto, flags):
socket.gaierror: [Errno -3] Temporary failure in name resolution

During handling of the above exception, another exception occurred:

Traceback (most recent call last):
  File "/home/julius/anaconda3/lib/python3.5/site-packages/telegram/vendor/ptb_urllib3/urllib3/connectionpool.py", line 617, in urlopen
    chunked=chunked)
  File "/home/julius/anaconda3/lib/python3.5/site-packages/telegram/vendor/ptb_urllib3/urllib3/connectionpool.py", line 360, in _make_request
    self._validate_conn(conn)
  File "/home/julius/anaconda3/lib/python3.5/site-packages/telegram/vendor/ptb_urllib3/urllib3/connectionpool.py", line 857, in _validate_conn
    super(HTTPSConnectionPool, self)._validate_conn(conn)
  File "/home/julius/anaconda3/lib/python3.5/site-packages/telegram/vendor/ptb_urllib3/urllib3/connectionpool.py", line 289, in _validate_conn
    conn.connect()
  File "/home/julius/anaconda3/lib/python3.5/site-packages/telegram/vendor/ptb_urllib3/urllib3/connection.py", line 284, in connect
    conn = self._new_conn()
  File "/home/julius/anaconda3/lib/python3.5/site-packages/telegram/vendor/ptb_urllib3/urllib3/connection.py", line 150, in _new_conn
    self, "Failed to establish a new connection: %s" % e)
telegram.vendor.ptb_urllib3.urllib3.exceptions.NewConnectionError: <telegram.vendor.ptb_urllib3.urllib3.connection.VerifiedHTTPSConnection object at 0x7f92d8080d68>: Failed to establish a new connection: [Errno -3] Temporary failure in name resolution

During handling of the above exception, another exception occurred:

Traceback (most recent call last):
  File "/home/julius/anaconda3/lib/python3.5/site-packages/telegram/utils/request.py", line 174, in _request_wrapper
    resp = self._con_pool.request(*args, **kwargs)
  File "/home/julius/anaconda3/lib/python3.5/site-packages/telegram/vendor/ptb_urllib3/urllib3/request.py", line 70, in request
    **urlopen_kw)
  File "/home/julius/anaconda3/lib/python3.5/site-packages/telegram/vendor/ptb_urllib3/urllib3/request.py", line 148, in request_encode_body
    return self.urlopen(method, url, **extra_kw)
  File "/home/julius/anaconda3/lib/python3.5/site-packages/telegram/vendor/ptb_urllib3/urllib3/poolmanager.py", line 244, in urlopen
    response = conn.urlopen(method, u.request_uri, **kw)
  File "/home/julius/anaconda3/lib/python3.5/site-packages/telegram/vendor/ptb_urllib3/urllib3/connectionpool.py", line 695, in urlopen
    **response_kw)
  File "/home/julius/anaconda3/lib/python3.5/site-packages/telegram/vendor/ptb_urllib3/urllib3/connectionpool.py", line 695, in urlopen
    **response_kw)
  File "/home/julius/anaconda3/lib/python3.5/site-packages/telegram/vendor/ptb_urllib3/urllib3/connectionpool.py", line 695, in urlopen
    **response_kw)
  File "/home/julius/anaconda3/lib/python3.5/site-packages/telegram/vendor/ptb_urllib3/urllib3/connectionpool.py", line 666, in urlopen
    _stacktrace=sys.exc_info()[2])
  File "/home/julius/anaconda3/lib/python3.5/site-packages/telegram/vendor/ptb_urllib3/urllib3/util/retry.py", line 376, in increment
    raise MaxRetryError(_pool, url, error or ResponseError(cause))
telegram.vendor.ptb_urllib3.urllib3.exceptions.MaxRetryError: HTTPSConnectionPool(host='api.telegram.org', port=443): Max retries exceeded with url: /bot350553078:AAEu70JDqMFcG_x5eBD3nqccTvc4aFNMKkg/sendMessage (Caused by NewConnectionError('<telegram.vendor.ptb_urllib3.urllib3.connection.VerifiedHTTPSConnection object at 0x7f92d8080d68>: Failed to establish a new connection: [Errno -3] Temporary failure in name resolution',))

During handling of the above exception, another exception occurred:

Traceback (most recent call last):
  File "/home/julius/anaconda3/lib/python3.5/site-packages/sacred/observers/telegram.py", line 119, in started_event
    parse_mode=telegram.ParseMode.MARKDOWN)
  File "/home/julius/anaconda3/lib/python3.5/site-packages/telegram/bot.py", line 52, in decorator
    result = func(self, *args, **kwargs)
  File "/home/julius/anaconda3/lib/python3.5/site-packages/telegram/bot.py", line 64, in decorator
    return self._message_wrapper(url, data, *args, **kwargs)
  File "/home/julius/anaconda3/lib/python3.5/site-packages/telegram/bot.py", line 156, in _message_wrapper
    result = self._request.post(url, data, timeout=kwargs.get('timeout'))
  File "/home/julius/anaconda3/lib/python3.5/site-packages/telegram/utils/request.py", line 252, in post
    **urlopen_kwargs)
  File "/home/julius/anaconda3/lib/python3.5/site-packages/telegram/utils/request.py", line 180, in _request_wrapper
    raise NetworkError('urllib3 HTTPError {0}'.format(error))
telegram.error.NetworkError: urllib3 HTTPError HTTPSConnectionPool(host='api.telegram.org', port=443): Max retries exceeded with url: /bot350553078:AAEu70JDqMFcG_x5eBD3nqccTvc4aFNMKkg/sendMessage (Caused by NewConnectionError('<telegram.vendor.ptb_urllib3.urllib3.connection.VerifiedHTTPSConnection object at 0x7f92d8080d68>: Failed to establish a new connection: [Errno -3] Temporary failure in name resolution',))
INFO - Bubble Sort - Started run with ID "459"

Experiment: Bubble Sort Test Experiment

INFO - Bubble Sort - Completed after 0:00:00
